[2024-06-24T09:37:35.896+0000] {local_task_job_runner.py:120} INFO - ::group::Pre task execution logs
[2024-06-24T09:37:35.912+0000] {taskinstance.py:2076} INFO - Dependencies all met for dep_context=non-requeueable deps ti=<TaskInstance: weather_dag.processing_tasks.inject_data_kyiv scheduled__2024-06-22T00:00:00+00:00 [queued]>
[2024-06-24T09:37:35.921+0000] {taskinstance.py:2076} INFO - Dependencies all met for dep_context=requeueable deps ti=<TaskInstance: weather_dag.processing_tasks.inject_data_kyiv scheduled__2024-06-22T00:00:00+00:00 [queued]>
[2024-06-24T09:37:35.921+0000] {taskinstance.py:2306} INFO - Starting attempt 1 of 1
[2024-06-24T09:37:35.937+0000] {taskinstance.py:2330} INFO - Executing <Task(PostgresOperator): processing_tasks.inject_data_kyiv> on 2024-06-22 00:00:00+00:00
[2024-06-24T09:37:35.944+0000] {warnings.py:112} WARNING - /home/***/.local/lib/python3.12/site-packages/***/task/task_runner/standard_task_runner.py:61: DeprecationWarning: This process (pid=104) is multi-threaded, use of fork() may lead to deadlocks in the child.
  pid = os.fork()

[2024-06-24T09:37:35.944+0000] {standard_task_runner.py:63} INFO - Started process 112 to run task
[2024-06-24T09:37:35.945+0000] {standard_task_runner.py:90} INFO - Running: ['***', 'tasks', 'run', 'weather_dag', 'processing_tasks.inject_data_kyiv', 'scheduled__2024-06-22T00:00:00+00:00', '--job-id', '16', '--raw', '--subdir', 'DAGS_FOLDER/weather_dag.py', '--cfg-path', '/tmp/tmpstd59rq4']
[2024-06-24T09:37:35.947+0000] {standard_task_runner.py:91} INFO - Job 16: Subtask processing_tasks.inject_data_kyiv
[2024-06-24T09:37:35.995+0000] {task_command.py:426} INFO - Running <TaskInstance: weather_dag.processing_tasks.inject_data_kyiv scheduled__2024-06-22T00:00:00+00:00 [running]> on host be890d2c7850
[2024-06-24T09:37:36.099+0000] {taskinstance.py:2648} INFO - Exporting env vars: AIRFLOW_CTX_DAG_OWNER='***' AIRFLOW_CTX_DAG_ID='weather_dag' AIRFLOW_CTX_TASK_ID='processing_tasks.inject_data_kyiv' AIRFLOW_CTX_EXECUTION_DATE='2024-06-22T00:00:00+00:00' AIRFLOW_CTX_TRY_NUMBER='1' AIRFLOW_CTX_DAG_RUN_ID='scheduled__2024-06-22T00:00:00+00:00'
[2024-06-24T09:37:36.101+0000] {taskinstance.py:430} INFO - ::endgroup::
[2024-06-24T09:37:36.102+0000] {sql.py:276} INFO - Executing: 
            INSERT INTO measures (timestamp, temp, city) VALUES (to_timestamp(1719221100), 293.72, 'Kyiv');
            
[2024-06-24T09:37:36.108+0000] {taskinstance.py:441} INFO - ::group::Post task execution logs
[2024-06-24T09:37:36.115+0000] {taskinstance.py:2905} ERROR - Task failed with exception
Traceback (most recent call last):
  File "/home/airflow/.local/lib/python3.12/site-packages/airflow/models/taskinstance.py", line 465, in _execute_task
    result = _execute_callable(context=context, **execute_callable_kwargs)
             ^^^^^^^^^^^^^^^^^^^^^^^^^^^^^^^^^^^^^^^^^^^^^^^^^^^^^^^^^^^^^
  File "/home/airflow/.local/lib/python3.12/site-packages/airflow/models/taskinstance.py", line 432, in _execute_callable
    return execute_callable(context=context, **execute_callable_kwargs)
           ^^^^^^^^^^^^^^^^^^^^^^^^^^^^^^^^^^^^^^^^^^^^^^^^^^^^^^^^^^^^
  File "/home/airflow/.local/lib/python3.12/site-packages/airflow/models/baseoperator.py", line 401, in wrapper
    return func(self, *args, **kwargs)
           ^^^^^^^^^^^^^^^^^^^^^^^^^^^
  File "/home/airflow/.local/lib/python3.12/site-packages/airflow/providers/common/sql/operators/sql.py", line 277, in execute
    hook = self.get_db_hook()
           ^^^^^^^^^^^^^^^^^^
  File "/home/airflow/.local/lib/python3.12/site-packages/airflow/providers/common/sql/operators/sql.py", line 188, in get_db_hook
    return self._hook
           ^^^^^^^^^^
  File "/usr/local/lib/python3.12/functools.py", line 995, in __get__
    val = self.func(instance)
          ^^^^^^^^^^^^^^^^^^^
  File "/home/airflow/.local/lib/python3.12/site-packages/airflow/providers/common/sql/operators/sql.py", line 150, in _hook
    conn = BaseHook.get_connection(conn_id)
           ^^^^^^^^^^^^^^^^^^^^^^^^^^^^^^^^
  File "/home/airflow/.local/lib/python3.12/site-packages/airflow/hooks/base.py", line 83, in get_connection
    conn = Connection.get_connection_from_secrets(conn_id)
           ^^^^^^^^^^^^^^^^^^^^^^^^^^^^^^^^^^^^^^^^^^^^^^^
  File "/home/airflow/.local/lib/python3.12/site-packages/airflow/models/connection.py", line 519, in get_connection_from_secrets
    raise AirflowNotFoundException(f"The conn_id `{conn_id}` isn't defined")
airflow.exceptions.AirflowNotFoundException: The conn_id `db_conn` isn't defined
[2024-06-24T09:37:36.120+0000] {taskinstance.py:1206} INFO - Marking task as FAILED. dag_id=weather_dag, task_id=processing_tasks.inject_data_kyiv, run_id=scheduled__2024-06-22T00:00:00+00:00, execution_date=20240622T000000, start_date=20240624T093735, end_date=20240624T093736
[2024-06-24T09:37:36.132+0000] {standard_task_runner.py:110} ERROR - Failed to execute job 16 for task processing_tasks.inject_data_kyiv (The conn_id `db_conn` isn't defined; 112)
[2024-06-24T09:37:36.159+0000] {local_task_job_runner.py:240} INFO - Task exited with return code 1
[2024-06-24T09:37:36.167+0000] {local_task_job_runner.py:222} INFO - ::endgroup::
