[2024-06-24T09:54:07.656+0000] {local_task_job_runner.py:120} INFO - ::group::Pre task execution logs
[2024-06-24T09:54:07.678+0000] {taskinstance.py:2076} INFO - Dependencies all met for dep_context=non-requeueable deps ti=<TaskInstance: weather_dag.processing_tasks.inject_data_lviv scheduled__2024-06-22T00:00:00+00:00 [queued]>
[2024-06-24T09:54:07.689+0000] {taskinstance.py:2076} INFO - Dependencies all met for dep_context=requeueable deps ti=<TaskInstance: weather_dag.processing_tasks.inject_data_lviv scheduled__2024-06-22T00:00:00+00:00 [queued]>
[2024-06-24T09:54:07.689+0000] {taskinstance.py:2306} INFO - Starting attempt 3 of 3
[2024-06-24T09:54:07.712+0000] {taskinstance.py:2330} INFO - Executing <Task(PostgresOperator): processing_tasks.inject_data_lviv> on 2024-06-22 00:00:00+00:00
[2024-06-24T09:54:07.720+0000] {warnings.py:112} WARNING - /home/***/.local/lib/python3.12/site-packages/***/task/task_runner/standard_task_runner.py:61: DeprecationWarning: This process (pid=388) is multi-threaded, use of fork() may lead to deadlocks in the child.
  pid = os.fork()

[2024-06-24T09:54:07.722+0000] {standard_task_runner.py:63} INFO - Started process 392 to run task
[2024-06-24T09:54:07.722+0000] {standard_task_runner.py:90} INFO - Running: ['***', 'tasks', 'run', 'weather_dag', 'processing_tasks.inject_data_lviv', 'scheduled__2024-06-22T00:00:00+00:00', '--job-id', '32', '--raw', '--subdir', 'DAGS_FOLDER/weather_dag.py', '--cfg-path', '/tmp/tmpd66qg_sc']
[2024-06-24T09:54:07.726+0000] {standard_task_runner.py:91} INFO - Job 32: Subtask processing_tasks.inject_data_lviv
[2024-06-24T09:54:07.783+0000] {task_command.py:426} INFO - Running <TaskInstance: weather_dag.processing_tasks.inject_data_lviv scheduled__2024-06-22T00:00:00+00:00 [running]> on host be890d2c7850
[2024-06-24T09:54:07.907+0000] {taskinstance.py:2648} INFO - Exporting env vars: AIRFLOW_CTX_DAG_OWNER='***' AIRFLOW_CTX_DAG_ID='weather_dag' AIRFLOW_CTX_TASK_ID='processing_tasks.inject_data_lviv' AIRFLOW_CTX_EXECUTION_DATE='2024-06-22T00:00:00+00:00' AIRFLOW_CTX_TRY_NUMBER='3' AIRFLOW_CTX_DAG_RUN_ID='scheduled__2024-06-22T00:00:00+00:00'
[2024-06-24T09:54:07.909+0000] {taskinstance.py:430} INFO - ::endgroup::
[2024-06-24T09:54:07.910+0000] {sql.py:276} INFO - Executing: 
            INSERT INTO measures (timestamp, temp, city) VALUES (to_timestamp(1719222717), 293.9, 'Lviv');
            
[2024-06-24T09:54:07.918+0000] {base.py:84} INFO - Using connection ID 'ps_db_conn' for task execution.
[2024-06-24T09:54:07.927+0000] {base.py:84} INFO - Using connection ID 'ps_db_conn' for task execution.
[2024-06-24T09:54:07.929+0000] {taskinstance.py:441} INFO - ::group::Post task execution logs
[2024-06-24T09:54:07.929+0000] {taskinstance.py:2905} ERROR - Task failed with exception
Traceback (most recent call last):
  File "/home/airflow/.local/lib/python3.12/site-packages/airflow/models/taskinstance.py", line 465, in _execute_task
    result = _execute_callable(context=context, **execute_callable_kwargs)
             ^^^^^^^^^^^^^^^^^^^^^^^^^^^^^^^^^^^^^^^^^^^^^^^^^^^^^^^^^^^^^
  File "/home/airflow/.local/lib/python3.12/site-packages/airflow/models/taskinstance.py", line 432, in _execute_callable
    return execute_callable(context=context, **execute_callable_kwargs)
           ^^^^^^^^^^^^^^^^^^^^^^^^^^^^^^^^^^^^^^^^^^^^^^^^^^^^^^^^^^^^
  File "/home/airflow/.local/lib/python3.12/site-packages/airflow/models/baseoperator.py", line 401, in wrapper
    return func(self, *args, **kwargs)
           ^^^^^^^^^^^^^^^^^^^^^^^^^^^
  File "/home/airflow/.local/lib/python3.12/site-packages/airflow/providers/common/sql/operators/sql.py", line 282, in execute
    output = hook.run(
             ^^^^^^^^^
  File "/home/airflow/.local/lib/python3.12/site-packages/airflow/providers/common/sql/hooks/sql.py", line 431, in run
    with self._create_autocommit_connection(autocommit) as conn:
  File "/usr/local/lib/python3.12/contextlib.py", line 137, in __enter__
    return next(self.gen)
           ^^^^^^^^^^^^^^
  File "/home/airflow/.local/lib/python3.12/site-packages/airflow/providers/common/sql/hooks/sql.py", line 551, in _create_autocommit_connection
    with closing(self.get_conn()) as conn:
                 ^^^^^^^^^^^^^^^
  File "/home/airflow/.local/lib/python3.12/site-packages/airflow/providers/postgres/hooks/postgres.py", line 175, in get_conn
    self.conn = psycopg2.connect(**conn_args)
                ^^^^^^^^^^^^^^^^^^^^^^^^^^^^^
  File "/home/airflow/.local/lib/python3.12/site-packages/psycopg2/__init__.py", line 122, in connect
    conn = _connect(dsn, connection_factory=connection_factory, **kwasync)
           ^^^^^^^^^^^^^^^^^^^^^^^^^^^^^^^^^^^^^^^^^^^^^^^^^^^^^^^^^^^^^^^
psycopg2.OperationalError: connection to server at "localhost" (127.0.0.1), port 5432 failed: Connection refused
	Is the server running on that host and accepting TCP/IP connections?
connection to server at "localhost" (::1), port 5432 failed: Cannot assign requested address
	Is the server running on that host and accepting TCP/IP connections?

[2024-06-24T09:54:07.939+0000] {taskinstance.py:1206} INFO - Marking task as FAILED. dag_id=weather_dag, task_id=processing_tasks.inject_data_lviv, run_id=scheduled__2024-06-22T00:00:00+00:00, execution_date=20240622T000000, start_date=20240624T095407, end_date=20240624T095407
[2024-06-24T09:54:07.954+0000] {standard_task_runner.py:110} ERROR - Failed to execute job 32 for task processing_tasks.inject_data_lviv (connection to server at "localhost" (127.0.0.1), port 5432 failed: Connection refused
	Is the server running on that host and accepting TCP/IP connections?
connection to server at "localhost" (::1), port 5432 failed: Cannot assign requested address
	Is the server running on that host and accepting TCP/IP connections?
; 392)
[2024-06-24T09:54:07.976+0000] {local_task_job_runner.py:240} INFO - Task exited with return code 1
[2024-06-24T09:54:07.987+0000] {local_task_job_runner.py:222} INFO - ::endgroup::
