[2024-06-24T10:58:20.525+0000] {local_task_job_runner.py:120} INFO - ::group::Pre task execution logs
[2024-06-24T10:58:20.548+0000] {taskinstance.py:2076} INFO - Dependencies all met for dep_context=non-requeueable deps ti=<TaskInstance: weather_dag.processing_tasks.inject_data_lviv scheduled__2024-06-22T00:00:00+00:00 [queued]>
[2024-06-24T10:58:20.559+0000] {taskinstance.py:2076} INFO - Dependencies all met for dep_context=requeueable deps ti=<TaskInstance: weather_dag.processing_tasks.inject_data_lviv scheduled__2024-06-22T00:00:00+00:00 [queued]>
[2024-06-24T10:58:20.559+0000] {taskinstance.py:2306} INFO - Starting attempt 5 of 5
[2024-06-24T10:58:20.578+0000] {taskinstance.py:2330} INFO - Executing <Task(PostgresOperator): processing_tasks.inject_data_lviv> on 2024-06-22 00:00:00+00:00
[2024-06-24T10:58:20.585+0000] {warnings.py:112} WARNING - /home/***/.local/lib/python3.12/site-packages/***/task/task_runner/standard_task_runner.py:61: DeprecationWarning: This process (pid=856) is multi-threaded, use of fork() may lead to deadlocks in the child.
  pid = os.fork()

[2024-06-24T10:58:20.587+0000] {standard_task_runner.py:63} INFO - Started process 862 to run task
[2024-06-24T10:58:20.587+0000] {standard_task_runner.py:90} INFO - Running: ['***', 'tasks', 'run', 'weather_dag', 'processing_tasks.inject_data_lviv', 'scheduled__2024-06-22T00:00:00+00:00', '--job-id', '83', '--raw', '--subdir', 'DAGS_FOLDER/weather_dag.py', '--cfg-path', '/tmp/tmppjb061pw']
[2024-06-24T10:58:20.590+0000] {standard_task_runner.py:91} INFO - Job 83: Subtask processing_tasks.inject_data_lviv
[2024-06-24T10:58:20.643+0000] {task_command.py:426} INFO - Running <TaskInstance: weather_dag.processing_tasks.inject_data_lviv scheduled__2024-06-22T00:00:00+00:00 [running]> on host afc8096e8b86
[2024-06-24T10:58:20.790+0000] {taskinstance.py:2648} INFO - Exporting env vars: AIRFLOW_CTX_DAG_OWNER='***' AIRFLOW_CTX_DAG_ID='weather_dag' AIRFLOW_CTX_TASK_ID='processing_tasks.inject_data_lviv' AIRFLOW_CTX_EXECUTION_DATE='2024-06-22T00:00:00+00:00' AIRFLOW_CTX_TRY_NUMBER='5' AIRFLOW_CTX_DAG_RUN_ID='scheduled__2024-06-22T00:00:00+00:00'
[2024-06-24T10:58:20.792+0000] {taskinstance.py:430} INFO - ::endgroup::
[2024-06-24T10:58:20.793+0000] {sql.py:276} INFO - Executing: 
            INSERT INTO measures (timestamp, temp, city, humidity, clouds, wind_speed) 
            VALUES (to_timestamp(1719226738), 
                   295.26,
                   51,
                   49,
                   4.43,
                   'Lviv'
            );
[2024-06-24T10:58:20.803+0000] {base.py:84} INFO - Using connection ID 'ps_db_conn' for task execution.
[2024-06-24T10:58:20.814+0000] {base.py:84} INFO - Using connection ID 'ps_db_conn' for task execution.
[2024-06-24T10:58:20.818+0000] {sql.py:487} INFO - Running statement: 
            INSERT INTO measures (timestamp, temp, city, humidity, clouds, wind_speed) 
            VALUES (to_timestamp(1719226738), 
                   295.26,
                   51,
                   49,
                   4.43,
                   'Lviv'
            );, parameters: None
[2024-06-24T10:58:20.820+0000] {taskinstance.py:441} INFO - ::group::Post task execution logs
[2024-06-24T10:58:20.820+0000] {taskinstance.py:2905} ERROR - Task failed with exception
Traceback (most recent call last):
  File "/home/airflow/.local/lib/python3.12/site-packages/airflow/models/taskinstance.py", line 465, in _execute_task
    result = _execute_callable(context=context, **execute_callable_kwargs)
             ^^^^^^^^^^^^^^^^^^^^^^^^^^^^^^^^^^^^^^^^^^^^^^^^^^^^^^^^^^^^^
  File "/home/airflow/.local/lib/python3.12/site-packages/airflow/models/taskinstance.py", line 432, in _execute_callable
    return execute_callable(context=context, **execute_callable_kwargs)
           ^^^^^^^^^^^^^^^^^^^^^^^^^^^^^^^^^^^^^^^^^^^^^^^^^^^^^^^^^^^^
  File "/home/airflow/.local/lib/python3.12/site-packages/airflow/models/baseoperator.py", line 401, in wrapper
    return func(self, *args, **kwargs)
           ^^^^^^^^^^^^^^^^^^^^^^^^^^^
  File "/home/airflow/.local/lib/python3.12/site-packages/airflow/providers/common/sql/operators/sql.py", line 282, in execute
    output = hook.run(
             ^^^^^^^^^
  File "/home/airflow/.local/lib/python3.12/site-packages/airflow/providers/common/sql/hooks/sql.py", line 435, in run
    self._run_command(cur, sql_statement, parameters)
  File "/home/airflow/.local/lib/python3.12/site-packages/airflow/providers/common/sql/hooks/sql.py", line 492, in _run_command
    cur.execute(sql_statement)
psycopg2.errors.UndefinedColumn: column "humidity" of relation "measures" does not exist
LINE 2: ...     INSERT INTO measures (timestamp, temp, city, humidity, ...
                                                             ^

[2024-06-24T10:58:20.830+0000] {taskinstance.py:1206} INFO - Marking task as FAILED. dag_id=weather_dag, task_id=processing_tasks.inject_data_lviv, run_id=scheduled__2024-06-22T00:00:00+00:00, execution_date=20240622T000000, start_date=20240624T105820, end_date=20240624T105820
[2024-06-24T10:58:20.846+0000] {standard_task_runner.py:110} ERROR - Failed to execute job 83 for task processing_tasks.inject_data_lviv (column "humidity" of relation "measures" does not exist
LINE 2: ...     INSERT INTO measures (timestamp, temp, city, humidity, ...
                                                             ^
; 862)
[2024-06-24T10:58:20.881+0000] {local_task_job_runner.py:240} INFO - Task exited with return code 1
[2024-06-24T10:58:20.900+0000] {taskinstance.py:3503} INFO - 0 downstream tasks scheduled from follow-on schedule check
[2024-06-24T10:58:20.904+0000] {local_task_job_runner.py:222} INFO - ::endgroup::
