[2024-06-24T10:58:20.527+0000] {local_task_job_runner.py:120} INFO - ::group::Pre task execution logs
[2024-06-24T10:58:20.551+0000] {taskinstance.py:2076} INFO - Dependencies all met for dep_context=non-requeueable deps ti=<TaskInstance: weather_dag.processing_tasks.inject_data_odesa scheduled__2024-06-22T00:00:00+00:00 [queued]>
[2024-06-24T10:58:20.561+0000] {taskinstance.py:2076} INFO - Dependencies all met for dep_context=requeueable deps ti=<TaskInstance: weather_dag.processing_tasks.inject_data_odesa scheduled__2024-06-22T00:00:00+00:00 [queued]>
[2024-06-24T10:58:20.562+0000] {taskinstance.py:2306} INFO - Starting attempt 1 of 1
[2024-06-24T10:58:20.585+0000] {taskinstance.py:2330} INFO - Executing <Task(PostgresOperator): processing_tasks.inject_data_odesa> on 2024-06-22 00:00:00+00:00
[2024-06-24T10:58:20.594+0000] {warnings.py:112} WARNING - /home/***/.local/lib/python3.12/site-packages/***/task/task_runner/standard_task_runner.py:61: DeprecationWarning: This process (pid=858) is multi-threaded, use of fork() may lead to deadlocks in the child.
  pid = os.fork()

[2024-06-24T10:58:20.596+0000] {standard_task_runner.py:63} INFO - Started process 863 to run task
[2024-06-24T10:58:20.596+0000] {standard_task_runner.py:90} INFO - Running: ['***', 'tasks', 'run', 'weather_dag', 'processing_tasks.inject_data_odesa', 'scheduled__2024-06-22T00:00:00+00:00', '--job-id', '82', '--raw', '--subdir', 'DAGS_FOLDER/weather_dag.py', '--cfg-path', '/tmp/tmpsy1950sw']
[2024-06-24T10:58:20.600+0000] {standard_task_runner.py:91} INFO - Job 82: Subtask processing_tasks.inject_data_odesa
[2024-06-24T10:58:20.653+0000] {task_command.py:426} INFO - Running <TaskInstance: weather_dag.processing_tasks.inject_data_odesa scheduled__2024-06-22T00:00:00+00:00 [running]> on host afc8096e8b86
[2024-06-24T10:58:20.803+0000] {taskinstance.py:2648} INFO - Exporting env vars: AIRFLOW_CTX_DAG_OWNER='***' AIRFLOW_CTX_DAG_ID='weather_dag' AIRFLOW_CTX_TASK_ID='processing_tasks.inject_data_odesa' AIRFLOW_CTX_EXECUTION_DATE='2024-06-22T00:00:00+00:00' AIRFLOW_CTX_TRY_NUMBER='1' AIRFLOW_CTX_DAG_RUN_ID='scheduled__2024-06-22T00:00:00+00:00'
[2024-06-24T10:58:20.806+0000] {taskinstance.py:430} INFO - ::endgroup::
[2024-06-24T10:58:20.807+0000] {sql.py:276} INFO - Executing: 
            INSERT INTO measures (timestamp, temp, city, humidity, clouds, wind_speed) 
            VALUES (to_timestamp(1719226738), 
                   299.29,
                   58,
                   99,
                   3.59,
                   'Odesa'
            );
[2024-06-24T10:58:20.816+0000] {base.py:84} INFO - Using connection ID 'ps_db_conn' for task execution.
[2024-06-24T10:58:20.826+0000] {base.py:84} INFO - Using connection ID 'ps_db_conn' for task execution.
[2024-06-24T10:58:20.831+0000] {sql.py:487} INFO - Running statement: 
            INSERT INTO measures (timestamp, temp, city, humidity, clouds, wind_speed) 
            VALUES (to_timestamp(1719226738), 
                   299.29,
                   58,
                   99,
                   3.59,
                   'Odesa'
            );, parameters: None
[2024-06-24T10:58:20.832+0000] {taskinstance.py:441} INFO - ::group::Post task execution logs
[2024-06-24T10:58:20.832+0000] {taskinstance.py:2905} ERROR - Task failed with exception
Traceback (most recent call last):
  File "/home/airflow/.local/lib/python3.12/site-packages/airflow/models/taskinstance.py", line 465, in _execute_task
    result = _execute_callable(context=context, **execute_callable_kwargs)
             ^^^^^^^^^^^^^^^^^^^^^^^^^^^^^^^^^^^^^^^^^^^^^^^^^^^^^^^^^^^^^
  File "/home/airflow/.local/lib/python3.12/site-packages/airflow/models/taskinstance.py", line 432, in _execute_callable
    return execute_callable(context=context, **execute_callable_kwargs)
           ^^^^^^^^^^^^^^^^^^^^^^^^^^^^^^^^^^^^^^^^^^^^^^^^^^^^^^^^^^^^
  File "/home/airflow/.local/lib/python3.12/site-packages/airflow/models/baseoperator.py", line 401, in wrapper
    return func(self, *args, **kwargs)
           ^^^^^^^^^^^^^^^^^^^^^^^^^^^
  File "/home/airflow/.local/lib/python3.12/site-packages/airflow/providers/common/sql/operators/sql.py", line 282, in execute
    output = hook.run(
             ^^^^^^^^^
  File "/home/airflow/.local/lib/python3.12/site-packages/airflow/providers/common/sql/hooks/sql.py", line 435, in run
    self._run_command(cur, sql_statement, parameters)
  File "/home/airflow/.local/lib/python3.12/site-packages/airflow/providers/common/sql/hooks/sql.py", line 492, in _run_command
    cur.execute(sql_statement)
psycopg2.errors.UndefinedColumn: column "humidity" of relation "measures" does not exist
LINE 2: ...     INSERT INTO measures (timestamp, temp, city, humidity, ...
                                                             ^

[2024-06-24T10:58:20.843+0000] {taskinstance.py:1206} INFO - Marking task as FAILED. dag_id=weather_dag, task_id=processing_tasks.inject_data_odesa, run_id=scheduled__2024-06-22T00:00:00+00:00, execution_date=20240622T000000, start_date=20240624T105820, end_date=20240624T105820
[2024-06-24T10:58:20.860+0000] {standard_task_runner.py:110} ERROR - Failed to execute job 82 for task processing_tasks.inject_data_odesa (column "humidity" of relation "measures" does not exist
LINE 2: ...     INSERT INTO measures (timestamp, temp, city, humidity, ...
                                                             ^
; 863)
[2024-06-24T10:58:20.890+0000] {local_task_job_runner.py:240} INFO - Task exited with return code 1
[2024-06-24T10:58:20.900+0000] {local_task_job_runner.py:222} INFO - ::endgroup::
