[2024-06-24T11:04:54.901+0000] {local_task_job_runner.py:120} INFO - ::group::Pre task execution logs
[2024-06-24T11:04:54.933+0000] {taskinstance.py:2076} INFO - Dependencies all met for dep_context=non-requeueable deps ti=<TaskInstance: weather_dag.processing_tasks.inject_data_odesa scheduled__2024-06-22T00:00:00+00:00 [queued]>
[2024-06-24T11:04:54.950+0000] {taskinstance.py:2076} INFO - Dependencies all met for dep_context=requeueable deps ti=<TaskInstance: weather_dag.processing_tasks.inject_data_odesa scheduled__2024-06-22T00:00:00+00:00 [queued]>
[2024-06-24T11:04:54.951+0000] {taskinstance.py:2306} INFO - Starting attempt 2 of 2
[2024-06-24T11:04:54.974+0000] {taskinstance.py:2330} INFO - Executing <Task(PostgresOperator): processing_tasks.inject_data_odesa> on 2024-06-22 00:00:00+00:00
[2024-06-24T11:04:54.985+0000] {warnings.py:112} WARNING - /home/***/.local/lib/python3.12/site-packages/***/task/task_runner/standard_task_runner.py:61: DeprecationWarning: This process (pid=988) is multi-threaded, use of fork() may lead to deadlocks in the child.
  pid = os.fork()

[2024-06-24T11:04:54.986+0000] {standard_task_runner.py:63} INFO - Started process 994 to run task
[2024-06-24T11:04:54.988+0000] {standard_task_runner.py:90} INFO - Running: ['***', 'tasks', 'run', 'weather_dag', 'processing_tasks.inject_data_odesa', 'scheduled__2024-06-22T00:00:00+00:00', '--job-id', '98', '--raw', '--subdir', 'DAGS_FOLDER/weather_dag.py', '--cfg-path', '/tmp/tmpk30t2ecl']
[2024-06-24T11:04:54.992+0000] {standard_task_runner.py:91} INFO - Job 98: Subtask processing_tasks.inject_data_odesa
[2024-06-24T11:04:55.064+0000] {task_command.py:426} INFO - Running <TaskInstance: weather_dag.processing_tasks.inject_data_odesa scheduled__2024-06-22T00:00:00+00:00 [running]> on host afc8096e8b86
[2024-06-24T11:04:55.253+0000] {taskinstance.py:2648} INFO - Exporting env vars: AIRFLOW_CTX_DAG_OWNER='***' AIRFLOW_CTX_DAG_ID='weather_dag' AIRFLOW_CTX_TASK_ID='processing_tasks.inject_data_odesa' AIRFLOW_CTX_EXECUTION_DATE='2024-06-22T00:00:00+00:00' AIRFLOW_CTX_TRY_NUMBER='2' AIRFLOW_CTX_DAG_RUN_ID='scheduled__2024-06-22T00:00:00+00:00'
[2024-06-24T11:04:55.257+0000] {taskinstance.py:430} INFO - ::endgroup::
[2024-06-24T11:04:55.257+0000] {sql.py:276} INFO - Executing: 
            INSERT INTO public.measures (timestamp, temp, city, humidity, clouds, wind_speed)
            VALUES (to_timestamp(1719227131), 
                   299.29,
                   58,
                   99,
                   3.59,
                   'Odesa'
            );
[2024-06-24T11:04:55.268+0000] {base.py:84} INFO - Using connection ID 'ps_db_conn' for task execution.
[2024-06-24T11:04:55.281+0000] {base.py:84} INFO - Using connection ID 'ps_db_conn' for task execution.
[2024-06-24T11:04:55.286+0000] {sql.py:487} INFO - Running statement: 
            INSERT INTO public.measures (timestamp, temp, city, humidity, clouds, wind_speed)
            VALUES (to_timestamp(1719227131), 
                   299.29,
                   58,
                   99,
                   3.59,
                   'Odesa'
            );, parameters: None
[2024-06-24T11:04:55.288+0000] {taskinstance.py:441} INFO - ::group::Post task execution logs
[2024-06-24T11:04:55.289+0000] {taskinstance.py:2905} ERROR - Task failed with exception
Traceback (most recent call last):
  File "/home/airflow/.local/lib/python3.12/site-packages/airflow/models/taskinstance.py", line 465, in _execute_task
    result = _execute_callable(context=context, **execute_callable_kwargs)
             ^^^^^^^^^^^^^^^^^^^^^^^^^^^^^^^^^^^^^^^^^^^^^^^^^^^^^^^^^^^^^
  File "/home/airflow/.local/lib/python3.12/site-packages/airflow/models/taskinstance.py", line 432, in _execute_callable
    return execute_callable(context=context, **execute_callable_kwargs)
           ^^^^^^^^^^^^^^^^^^^^^^^^^^^^^^^^^^^^^^^^^^^^^^^^^^^^^^^^^^^^
  File "/home/airflow/.local/lib/python3.12/site-packages/airflow/models/baseoperator.py", line 401, in wrapper
    return func(self, *args, **kwargs)
           ^^^^^^^^^^^^^^^^^^^^^^^^^^^
  File "/home/airflow/.local/lib/python3.12/site-packages/airflow/providers/common/sql/operators/sql.py", line 282, in execute
    output = hook.run(
             ^^^^^^^^^
  File "/home/airflow/.local/lib/python3.12/site-packages/airflow/providers/common/sql/hooks/sql.py", line 435, in run
    self._run_command(cur, sql_statement, parameters)
  File "/home/airflow/.local/lib/python3.12/site-packages/airflow/providers/common/sql/hooks/sql.py", line 492, in _run_command
    cur.execute(sql_statement)
psycopg2.errors.InvalidTextRepresentation: invalid input syntax for type real: "Odesa"
LINE 8:                    'Odesa'
                           ^

[2024-06-24T11:04:55.302+0000] {taskinstance.py:1206} INFO - Marking task as FAILED. dag_id=weather_dag, task_id=processing_tasks.inject_data_odesa, run_id=scheduled__2024-06-22T00:00:00+00:00, execution_date=20240622T000000, start_date=20240624T110454, end_date=20240624T110455
[2024-06-24T11:04:55.319+0000] {standard_task_runner.py:110} ERROR - Failed to execute job 98 for task processing_tasks.inject_data_odesa (invalid input syntax for type real: "Odesa"
LINE 8:                    'Odesa'
                           ^
; 994)
[2024-06-24T11:04:55.362+0000] {local_task_job_runner.py:240} INFO - Task exited with return code 1
[2024-06-24T11:04:55.384+0000] {taskinstance.py:3503} INFO - 0 downstream tasks scheduled from follow-on schedule check
[2024-06-24T11:04:55.387+0000] {local_task_job_runner.py:222} INFO - ::endgroup::
