[2024-06-24T11:33:05.795+0000] {local_task_job_runner.py:120} INFO - ::group::Pre task execution logs
[2024-06-24T11:33:05.818+0000] {taskinstance.py:2076} INFO - Dependencies all met for dep_context=non-requeueable deps ti=<TaskInstance: weather_dag.processing_tasks.extract_data_odesa scheduled__2024-06-22T00:00:00+00:00 [queued]>
[2024-06-24T11:33:05.829+0000] {taskinstance.py:2076} INFO - Dependencies all met for dep_context=requeueable deps ti=<TaskInstance: weather_dag.processing_tasks.extract_data_odesa scheduled__2024-06-22T00:00:00+00:00 [queued]>
[2024-06-24T11:33:05.830+0000] {taskinstance.py:2306} INFO - Starting attempt 7 of 7
[2024-06-24T11:33:05.850+0000] {taskinstance.py:2330} INFO - Executing <Task(SimpleHttpOperator): processing_tasks.extract_data_odesa> on 2024-06-22 00:00:00+00:00
[2024-06-24T11:33:05.859+0000] {warnings.py:112} WARNING - /home/***/.local/lib/python3.12/site-packages/***/task/task_runner/standard_task_runner.py:61: DeprecationWarning: This process (pid=1504) is multi-threaded, use of fork() may lead to deadlocks in the child.
  pid = os.fork()

[2024-06-24T11:33:05.861+0000] {standard_task_runner.py:63} INFO - Started process 1517 to run task
[2024-06-24T11:33:05.863+0000] {standard_task_runner.py:90} INFO - Running: ['***', 'tasks', 'run', 'weather_dag', 'processing_tasks.extract_data_odesa', 'scheduled__2024-06-22T00:00:00+00:00', '--job-id', '136', '--raw', '--subdir', 'DAGS_FOLDER/weather_dag.py', '--cfg-path', '/tmp/tmpt7c0knoa']
[2024-06-24T11:33:05.867+0000] {standard_task_runner.py:91} INFO - Job 136: Subtask processing_tasks.extract_data_odesa
[2024-06-24T11:33:05.933+0000] {task_command.py:426} INFO - Running <TaskInstance: weather_dag.processing_tasks.extract_data_odesa scheduled__2024-06-22T00:00:00+00:00 [running]> on host afc8096e8b86
[2024-06-24T11:33:06.022+0000] {abstractoperator.py:725} ERROR - Exception rendering Jinja template for task 'processing_tasks.extract_data_odesa', field 'data'. Template: {'appid': '***', 'lat': '46.482952', 'lon': '30.71248', 'dt': "{{ti.xcom_pull(task_ids='get_execution_date_timestamp')[0]}}"}
Traceback (most recent call last):
  File "/home/airflow/.local/lib/python3.12/site-packages/airflow/models/abstractoperator.py", line 717, in _do_render_template_fields
    rendered_content = self.render_template(
                       ^^^^^^^^^^^^^^^^^^^^^
  File "/home/airflow/.local/lib/python3.12/site-packages/airflow/template/templater.py", line 181, in render_template
    return {k: self.render_template(v, context, jinja_env, oids) for k, v in value.items()}
               ^^^^^^^^^^^^^^^^^^^^^^^^^^^^^^^^^^^^^^^^^^^^^^^^^
  File "/home/airflow/.local/lib/python3.12/site-packages/airflow/template/templater.py", line 169, in render_template
    return self._render(template, context)
           ^^^^^^^^^^^^^^^^^^^^^^^^^^^^^^^
  File "/home/airflow/.local/lib/python3.12/site-packages/airflow/models/abstractoperator.py", line 675, in _render
    return super()._render(template, context, dag=dag)
           ^^^^^^^^^^^^^^^^^^^^^^^^^^^^^^^^^^^^^^^^^^^
  File "/home/airflow/.local/lib/python3.12/site-packages/airflow/template/templater.py", line 126, in _render
    return render_template_to_string(template, context)
           ^^^^^^^^^^^^^^^^^^^^^^^^^^^^^^^^^^^^^^^^^^^^
  File "/home/airflow/.local/lib/python3.12/site-packages/airflow/utils/helpers.py", line 289, in render_template_to_string
    return render_template(template, cast(MutableMapping[str, Any], context), native=False)
           ^^^^^^^^^^^^^^^^^^^^^^^^^^^^^^^^^^^^^^^^^^^^^^^^^^^^^^^^^^^^^^^^^^^^^^^^^^^^^^^^
  File "/home/airflow/.local/lib/python3.12/site-packages/airflow/utils/helpers.py", line 284, in render_template
    return "".join(nodes)
           ^^^^^^^^^^^^^^
  File "<template>", line 12, in root
  File "/home/airflow/.local/lib/python3.12/site-packages/jinja2/runtime.py", line 857, in _fail_with_undefined_error
    raise self._undefined_exception(self._undefined_message)
jinja2.exceptions.UndefinedError: int object has no element 0
[2024-06-24T11:33:06.025+0000] {taskinstance.py:2905} ERROR - Task failed with exception
Traceback (most recent call last):
  File "/home/airflow/.local/lib/python3.12/site-packages/airflow/models/taskinstance.py", line 2479, in _run_raw_task
    self._execute_task_with_callbacks(context, test_mode, session=session)
  File "/home/airflow/.local/lib/python3.12/site-packages/airflow/models/taskinstance.py", line 2633, in _execute_task_with_callbacks
    task_orig = self.render_templates(context=context, jinja_env=jinja_env)
                ^^^^^^^^^^^^^^^^^^^^^^^^^^^^^^^^^^^^^^^^^^^^^^^^^^^^^^^^^^^
  File "/home/airflow/.local/lib/python3.12/site-packages/airflow/models/taskinstance.py", line 3094, in render_templates
    original_task.render_template_fields(context, jinja_env)
  File "/home/airflow/.local/lib/python3.12/site-packages/airflow/models/baseoperator.py", line 1337, in render_template_fields
    self._do_render_template_fields(self, self.template_fields, context, jinja_env, set())
  File "/home/airflow/.local/lib/python3.12/site-packages/airflow/models/abstractoperator.py", line 717, in _do_render_template_fields
    rendered_content = self.render_template(
                       ^^^^^^^^^^^^^^^^^^^^^
  File "/home/airflow/.local/lib/python3.12/site-packages/airflow/template/templater.py", line 181, in render_template
    return {k: self.render_template(v, context, jinja_env, oids) for k, v in value.items()}
               ^^^^^^^^^^^^^^^^^^^^^^^^^^^^^^^^^^^^^^^^^^^^^^^^^
  File "/home/airflow/.local/lib/python3.12/site-packages/airflow/template/templater.py", line 169, in render_template
    return self._render(template, context)
           ^^^^^^^^^^^^^^^^^^^^^^^^^^^^^^^
  File "/home/airflow/.local/lib/python3.12/site-packages/airflow/models/abstractoperator.py", line 675, in _render
    return super()._render(template, context, dag=dag)
           ^^^^^^^^^^^^^^^^^^^^^^^^^^^^^^^^^^^^^^^^^^^
  File "/home/airflow/.local/lib/python3.12/site-packages/airflow/template/templater.py", line 126, in _render
    return render_template_to_string(template, context)
           ^^^^^^^^^^^^^^^^^^^^^^^^^^^^^^^^^^^^^^^^^^^^
  File "/home/airflow/.local/lib/python3.12/site-packages/airflow/utils/helpers.py", line 289, in render_template_to_string
    return render_template(template, cast(MutableMapping[str, Any], context), native=False)
           ^^^^^^^^^^^^^^^^^^^^^^^^^^^^^^^^^^^^^^^^^^^^^^^^^^^^^^^^^^^^^^^^^^^^^^^^^^^^^^^^
  File "/home/airflow/.local/lib/python3.12/site-packages/airflow/utils/helpers.py", line 284, in render_template
    return "".join(nodes)
           ^^^^^^^^^^^^^^
  File "<template>", line 12, in root
  File "/home/airflow/.local/lib/python3.12/site-packages/jinja2/runtime.py", line 857, in _fail_with_undefined_error
    raise self._undefined_exception(self._undefined_message)
jinja2.exceptions.UndefinedError: int object has no element 0
[2024-06-24T11:33:06.036+0000] {taskinstance.py:1206} INFO - Marking task as FAILED. dag_id=weather_dag, task_id=processing_tasks.extract_data_odesa, run_id=scheduled__2024-06-22T00:00:00+00:00, execution_date=20240622T000000, start_date=20240624T113305, end_date=20240624T113306
[2024-06-24T11:33:06.055+0000] {standard_task_runner.py:110} ERROR - Failed to execute job 136 for task processing_tasks.extract_data_odesa (int object has no element 0; 1517)
[2024-06-24T11:33:06.075+0000] {local_task_job_runner.py:240} INFO - Task exited with return code 1
[2024-06-24T11:33:06.087+0000] {local_task_job_runner.py:222} INFO - ::endgroup::
