[2024-06-24T11:35:37.126+0000] {local_task_job_runner.py:120} INFO - ::group::Pre task execution logs
[2024-06-24T11:35:37.147+0000] {taskinstance.py:2076} INFO - Dependencies all met for dep_context=non-requeueable deps ti=<TaskInstance: weather_dag.processing_tasks.process_data_odesa scheduled__2024-06-22T00:00:00+00:00 [queued]>
[2024-06-24T11:35:37.156+0000] {taskinstance.py:2076} INFO - Dependencies all met for dep_context=requeueable deps ti=<TaskInstance: weather_dag.processing_tasks.process_data_odesa scheduled__2024-06-22T00:00:00+00:00 [queued]>
[2024-06-24T11:35:37.156+0000] {taskinstance.py:2306} INFO - Starting attempt 6 of 6
[2024-06-24T11:35:37.171+0000] {taskinstance.py:2330} INFO - Executing <Task(PythonOperator): processing_tasks.process_data_odesa> on 2024-06-22 00:00:00+00:00
[2024-06-24T11:35:37.180+0000] {warnings.py:112} WARNING - /home/***/.local/lib/python3.12/site-packages/***/task/task_runner/standard_task_runner.py:61: DeprecationWarning: This process (pid=1578) is multi-threaded, use of fork() may lead to deadlocks in the child.
  pid = os.fork()

[2024-06-24T11:35:37.181+0000] {standard_task_runner.py:63} INFO - Started process 1584 to run task
[2024-06-24T11:35:37.182+0000] {standard_task_runner.py:90} INFO - Running: ['***', 'tasks', 'run', 'weather_dag', 'processing_tasks.process_data_odesa', 'scheduled__2024-06-22T00:00:00+00:00', '--job-id', '148', '--raw', '--subdir', 'DAGS_FOLDER/weather_dag.py', '--cfg-path', '/tmp/tmpslepu0bg']
[2024-06-24T11:35:37.184+0000] {standard_task_runner.py:91} INFO - Job 148: Subtask processing_tasks.process_data_odesa
[2024-06-24T11:35:37.239+0000] {task_command.py:426} INFO - Running <TaskInstance: weather_dag.processing_tasks.process_data_odesa scheduled__2024-06-22T00:00:00+00:00 [running]> on host afc8096e8b86
[2024-06-24T11:35:37.352+0000] {taskinstance.py:2648} INFO - Exporting env vars: AIRFLOW_CTX_DAG_OWNER='***' AIRFLOW_CTX_DAG_ID='weather_dag' AIRFLOW_CTX_TASK_ID='processing_tasks.process_data_odesa' AIRFLOW_CTX_EXECUTION_DATE='2024-06-22T00:00:00+00:00' AIRFLOW_CTX_TRY_NUMBER='6' AIRFLOW_CTX_DAG_RUN_ID='scheduled__2024-06-22T00:00:00+00:00'
[2024-06-24T11:35:37.354+0000] {taskinstance.py:430} INFO - ::endgroup::
[2024-06-24T11:35:37.366+0000] {taskinstance.py:441} INFO - ::group::Post task execution logs
[2024-06-24T11:35:37.367+0000] {taskinstance.py:2905} ERROR - Task failed with exception
Traceback (most recent call last):
  File "/home/airflow/.local/lib/python3.12/site-packages/airflow/models/taskinstance.py", line 465, in _execute_task
    result = _execute_callable(context=context, **execute_callable_kwargs)
             ^^^^^^^^^^^^^^^^^^^^^^^^^^^^^^^^^^^^^^^^^^^^^^^^^^^^^^^^^^^^^
  File "/home/airflow/.local/lib/python3.12/site-packages/airflow/models/taskinstance.py", line 432, in _execute_callable
    return execute_callable(context=context, **execute_callable_kwargs)
           ^^^^^^^^^^^^^^^^^^^^^^^^^^^^^^^^^^^^^^^^^^^^^^^^^^^^^^^^^^^^
  File "/home/airflow/.local/lib/python3.12/site-packages/airflow/models/baseoperator.py", line 401, in wrapper
    return func(self, *args, **kwargs)
           ^^^^^^^^^^^^^^^^^^^^^^^^^^^
  File "/home/airflow/.local/lib/python3.12/site-packages/airflow/operators/python.py", line 235, in execute
    return_value = self.execute_callable()
                   ^^^^^^^^^^^^^^^^^^^^^^^
  File "/home/airflow/.local/lib/python3.12/site-packages/airflow/operators/python.py", line 252, in execute_callable
    return self.python_callable(*self.op_args, **self.op_kwargs)
           ^^^^^^^^^^^^^^^^^^^^^^^^^^^^^^^^^^^^^^^^^^^^^^^^^^^^^
  File "/opt/airflow/dags/weather_dag.py", line 22, in _process_weather
    timestamp = info["dt"]
                ~~~~^^^^^^
KeyError: 'dt'
[2024-06-24T11:35:37.378+0000] {taskinstance.py:1206} INFO - Marking task as FAILED. dag_id=weather_dag, task_id=processing_tasks.process_data_odesa, run_id=scheduled__2024-06-22T00:00:00+00:00, execution_date=20240622T000000, start_date=20240624T113537, end_date=20240624T113537
[2024-06-24T11:35:37.394+0000] {standard_task_runner.py:110} ERROR - Failed to execute job 148 for task processing_tasks.process_data_odesa ('dt'; 1584)
[2024-06-24T11:35:37.437+0000] {local_task_job_runner.py:240} INFO - Task exited with return code 1
[2024-06-24T11:35:37.447+0000] {local_task_job_runner.py:222} INFO - ::endgroup::
